<?xml version="1.0" ?>
<!-- =================================================================================== -->
<!-- |    This document was autogenerated by xacro from /home/gepetto/ros2_ws/install/franka_description/share/franka_description/robots/fer/fer.urdf.xacro | -->
<!-- |    EDITING THIS FILE BY HAND IS NOT RECOMMENDED                                 | -->
<!-- =================================================================================== -->
<robot name="fer">
  <!-- safety_distance: Minimum safety distance in [m] by which the collision volumes are expanded and which is enforced during robot motions -->
  <!-- arm_id: Namespace of the robot arm. Serves to differentiate between arms in case of multiple instances. -->
  <!-- joint_limits: description of the joint limits that comes from a YAML file. Example definition: ${xacro.load_yaml('$(find franka_description)/robots/fr3/joint_limits.yaml')} -->
  <!-- kinematics: description of the kinematics that comes from a YAML file. Example definition: ${xacro.load_yaml('$(find franka_description)/robots/fr3/kinematics.yaml')} -->
  <!-- inertials: description of the inertials that comes from a YAML file. Example definition: ${xacro.load_yaml('$(find franka_description)/robots/fr3/inertials.yaml')} -->
  <!-- dynamics: description of the dynamics that comes from a YAML file. Example definition: ${xacro.load_yaml('$(find franka_description)/robots/fr3/dynamics.yaml')} -->
  <link name="base">
      </link>
  <joint name="fer_base_joint" type="fixed">
    <parent link="base"/>
    <child link="fer_link0"/>
    <origin rpy="0 0 0" xyz="0 0 0"/>
  </joint>
  <!-- sub-link defining detailed meshes for collision with environment -->
  <link name="fer_link0">
    <visual name="fer_link0_visual">
      <geometry>
        <mesh filename="package://franka_description/meshes/robot_arms/fer/visual/link0.dae"/>
      </geometry>
    </visual>
    <collision name="fer_link0_collision">
      <geometry>
        <mesh filename="package://franka_description/meshes/robot_arms/fer/collision/link0.stl"/>
      </geometry>
    </collision>
    <inertial>
      <origin rpy="0 0 0" xyz="-0.041018 -0.00014 0.049974"/>
      <mass value="0.629769"/>
      <inertia ixx="0.00315" ixy="8.2904e-07" ixz="0.00015" iyy="0.00388" iyz="8.2299e-06" izz="0.004285"/>
    </inertial>
  </link>
  <!-- sub-link defining detailed meshes for collision with environment -->
  <link name="fer_link1">
    <visual name="fer_link1_visual">
      <geometry>
        <mesh filename="package://franka_description/meshes/robot_arms/fer/visual/link1.dae"/>
      </geometry>
    </visual>
    <collision name="fer_link1_collision">
      <geometry>
        <mesh filename="package://franka_description/meshes/robot_arms/fer/collision/link1.stl"/>
      </geometry>
    </collision>
    <inertial>
      <origin rpy="0 0 0" xyz="0.003875 0.002081 -0.04762"/>
      <mass value="4.970684"/>
      <inertia ixx="0.70337" ixy="-0.000139" ixz="0.006772" iyy="0.70661" iyz="0.019169" izz="0.009117"/>
    </inertial>
  </link>
  <joint name="fer_joint1" type="revolute">
    <origin rpy="0 0 0" xyz="0 0 0.333"/>
    <parent link="fer_link0"/>
    <child link="fer_link1"/>
    <axis xyz="0 0 1"/>
    <limit effort="87.0" lower="-2.8973" upper="2.8973" velocity="2.175"/>
    <safety_controller k_position="100.0" k_velocity="40.0" soft_lower_limit="-2.8973" soft_upper_limit="2.8973"/>
    <dynamics D="1" K="7000" damping="0.003" friction="0.2" mu_coulomb="0" mu_viscous="16"/>
  </joint>
  <!-- sub-link defining detailed meshes for collision with environment -->
  <link name="fer_link2">
    <visual name="fer_link2_visual">
      <geometry>
        <mesh filename="package://franka_description/meshes/robot_arms/fer/visual/link2.dae"/>
      </geometry>
    </visual>
    <collision name="fer_link2_collision">
      <geometry>
        <mesh filename="package://franka_description/meshes/robot_arms/fer/collision/link2.stl"/>
      </geometry>
    </collision>
    <inertial>
      <origin rpy="0 0 0" xyz="-0.003141 -0.02872  0.003495"/>
      <mass value="0.646926"/>
      <inertia ixx="0.007962" ixy="-0.003925" ixz="0.010254" iyy="0.02811" iyz="0.000704" izz="0.025995"/>
    </inertial>
  </link>
  <joint name="fer_joint2" type="revolute">
    <origin rpy="-1.570796326794897 0 0" xyz="0 0 0"/>
    <parent link="fer_link1"/>
    <child link="fer_link2"/>
    <axis xyz="0 0 1"/>
    <limit effort="87.0" lower="-1.7628" upper="1.7628" velocity="2.175"/>
    <safety_controller k_position="100.0" k_velocity="40.0" soft_lower_limit="-1.7628" soft_upper_limit="1.7628"/>
    <dynamics D="1" K="7000" damping="0.003" friction="0.2" mu_coulomb="0" mu_viscous="16"/>
  </joint>
  <!-- sub-link defining detailed meshes for collision with environment -->
  <link name="fer_link3">
    <visual name="fer_link3_visual">
      <geometry>
        <mesh filename="package://franka_description/meshes/robot_arms/fer/visual/link3.dae"/>
      </geometry>
    </visual>
    <collision name="fer_link3_collision">
      <geometry>
        <mesh filename="package://franka_description/meshes/robot_arms/fer/collision/link3.stl"/>
      </geometry>
    </collision>
    <inertial>
      <origin rpy="0 0 0" xyz="2.7518e-02 3.9252e-02 -6.6502e-02"/>
      <mass value="3.228604"/>
      <inertia ixx="0.037242" ixy="-0.004761" ixz="-0.011396" iyy="0.036155" iyz="-0.012805" izz="0.01083"/>
    </inertial>
  </link>
  <joint name="fer_joint3" type="revolute">
    <origin rpy="1.570796326794897 0 0" xyz="0 -0.316 0"/>
    <parent link="fer_link2"/>
    <child link="fer_link3"/>
    <axis xyz="0 0 1"/>
    <limit effort="87.0" lower="-2.8973" upper="2.8973" velocity="2.175"/>
    <safety_controller k_position="100.0" k_velocity="40.0" soft_lower_limit="-2.8973" soft_upper_limit="2.8973"/>
    <dynamics D="1" K="7000" damping="0.003" friction="0.2" mu_coulomb="0" mu_viscous="16"/>
  </joint>
  <!-- sub-link defining detailed meshes for collision with environment -->
  <link name="fer_link4">
    <visual name="fer_link4_visual">
      <geometry>
        <mesh filename="package://franka_description/meshes/robot_arms/fer/visual/link4.dae"/>
      </geometry>
    </visual>
    <collision name="fer_link4_collision">
      <geometry>
        <mesh filename="package://franka_description/meshes/robot_arms/fer/collision/link4.stl"/>
      </geometry>
    </collision>
    <inertial>
      <origin rpy="0 0 0" xyz="-5.317e-02 1.04419e-01 2.7454e-02"/>
      <mass value="3.587895"/>
      <inertia ixx="0.025853" ixy="0.007796" ixz="-0.001332" iyy="0.019552" iyz="0.008641" izz="0.028323"/>
    </inertial>
  </link>
  <joint name="fer_joint4" type="revolute">
    <origin rpy="1.570796326794897 0 0" xyz="0.0825 0 0"/>
    <parent link="fer_link3"/>
    <child link="fer_link4"/>
    <axis xyz="0 0 1"/>
    <limit effort="87.0" lower="-3.0718" upper="-0.0698" velocity="2.175"/>
    <safety_controller k_position="100.0" k_velocity="40.0" soft_lower_limit="-3.0718" soft_upper_limit="-0.0698"/>
    <dynamics D="1" K="7000" damping="0.003" friction="0.2" mu_coulomb="0" mu_viscous="16"/>
  </joint>
  <!-- sub-link defining detailed meshes for collision with environment -->
  <link name="fer_link5">
    <visual name="fer_link5_visual">
      <geometry>
        <mesh filename="package://franka_description/meshes/robot_arms/fer/visual/link5.dae"/>
      </geometry>
    </visual>
    <collision name="fer_link5_collision">
      <geometry>
        <mesh filename="package://franka_description/meshes/robot_arms/fer/collision/link5.stl"/>
      </geometry>
    </collision>
    <inertial>
      <origin rpy="0 0 0" xyz="-1.1953e-02 4.1065e-02 -3.8437e-02"/>
      <mass value="1.225946"/>
      <inertia ixx="0.035549" ixy="-0.002117" ixz="-0.004037" iyy="0.029474" iyz="0.000229" izz="0.008627"/>
    </inertial>
  </link>
  <joint name="fer_joint5" type="revolute">
    <origin rpy="-1.570796326794897 0 0" xyz="-0.0825 0.384 0"/>
    <parent link="fer_link4"/>
    <child link="fer_link5"/>
    <axis xyz="0 0 1"/>
    <limit effort="12.0" lower="-2.8973" upper="2.8973" velocity="2.61"/>
    <safety_controller k_position="100.0" k_velocity="40.0" soft_lower_limit="-2.8973" soft_upper_limit="2.8973"/>
    <dynamics D="1" K="7000" damping="0.003" friction="0.2" mu_coulomb="0" mu_viscous="16"/>
  </joint>
  <!-- sub-link defining detailed meshes for collision with environment -->
  <link name="fer_link6">
    <visual name="fer_link6_visual">
      <geometry>
        <mesh filename="package://franka_description/meshes/robot_arms/fer/visual/link6.dae"/>
      </geometry>
    </visual>
    <collision name="fer_link6_collision">
      <geometry>
        <mesh filename="package://franka_description/meshes/robot_arms/fer/collision/link6.stl"/>
      </geometry>
    </collision>
    <inertial>
      <origin rpy="0 0 0" xyz="6.0149e-02 -1.4117e-02 -1.0517e-02"/>
      <mass value="1.666555"/>
      <inertia ixx="0.001964" ixy="0.000109" ixz="-0.001158" iyy="0.004354" iyz="0.000341" izz="0.005433"/>
    </inertial>
  </link>
  <joint name="fer_joint6" type="revolute">
    <origin rpy="1.570796326794897 0 0" xyz="0 0 0"/>
    <parent link="fer_link5"/>
    <child link="fer_link6"/>
    <axis xyz="0 0 1"/>
    <limit effort="12.0" lower="-0.0175" upper="3.7525" velocity="2.61"/>
    <safety_controller k_position="100.0" k_velocity="40.0" soft_lower_limit="-0.0175" soft_upper_limit="3.7525"/>
    <dynamics D="1" K="7000" damping="0.003" friction="0.2" mu_coulomb="0" mu_viscous="16"/>
  </joint>
  <!-- sub-link defining detailed meshes for collision with environment -->
  <link name="fer_link7">
    <visual name="fer_link7_visual">
      <geometry>
        <mesh filename="package://franka_description/meshes/robot_arms/fer/visual/link7.dae"/>
      </geometry>
    </visual>
    <collision name="fer_link7_collision">
      <geometry>
        <mesh filename="package://franka_description/meshes/robot_arms/fer/collision/link7.stl"/>
      </geometry>
    </collision>
    <inertial>
      <origin rpy="0 0 0" xyz="1.0517e-02 -4.252e-03 6.1597e-02"/>
      <mass value="0.735522"/>
      <inertia ixx="0.012516" ixy="-0.000428" ixz="-0.001196" iyy="0.010027" iyz="-0.000741" izz="0.004815"/>
    </inertial>
  </link>
  <joint name="fer_joint7" type="revolute">
    <origin rpy="1.570796326794897 0 0" xyz="0.088 0 0"/>
    <parent link="fer_link6"/>
    <child link="fer_link7"/>
    <axis xyz="0 0 1"/>
    <limit effort="12.0" lower="-2.8973" upper="2.8973" velocity="2.61"/>
    <safety_controller k_position="100.0" k_velocity="40.0" soft_lower_limit="-2.8973" soft_upper_limit="2.8973"/>
    <dynamics D="1" K="7000" damping="0.003" friction="0.2" mu_coulomb="0" mu_viscous="16"/>
  </joint>
  <link name="fer_link8"/>
  <joint name="fer_joint8" type="fixed">
    <origin rpy="0 0 0" xyz="0 0 0.107"/>
    <parent link="fer_link7"/>
    <child link="fer_link8"/>
  </joint>
  <joint name="fer_hand_joint" type="fixed">
    <parent link="ati_mini45_tool_mount"/>
    <child link="fer_hand"/>
    <origin rpy="0 0 -0.7853981633974483" xyz="0 0 0"/>
  </joint>
  <!-- sub-link defining detailed meshes for collision with environment -->
  <link name="fer_hand">
    <visual name="fer_hand_visual">
      <geometry>
        <mesh filename="package://franka_description/meshes/robot_ee/franka_hand_white/visual/hand.dae"/>
      </geometry>
    </visual>
    <collision name="fer_hand_collision">
      <geometry>
        <mesh filename="package://franka_description/meshes/robot_ee/franka_hand_white/collision/hand.stl"/>
      </geometry>
    </collision>
    <inertial>
      <origin rpy="0 0 0" xyz="-0.01 0 0.03"/>
      <mass value="0.73"/>
      <inertia ixx="0.001" ixy="0" ixz="0" iyy="0.0025" iyz="0" izz="0.0017"/>
    </inertial>
  </link>
  <!-- Define the hand_tcp frame -->
  <link name="fer_hand_tcp"/>
  <joint name="fer_hand_tcp_joint" type="fixed">
    <origin rpy="0 0 0" xyz="0 0 0.1034"/>
    <parent link="fer_hand"/>
    <child link="fer_hand_tcp"/>
  </joint>
  <link name="fer_leftfinger">
    <visual name="fer_leftfinger_visual">
      <geometry>
        <mesh filename="package://franka_description/meshes/robot_ee/franka_hand_white/visual/finger.dae"/>
      </geometry>
    </visual>
    <!-- screw mount -->
    <collision>
      <origin rpy="0 0 0" xyz="0 18.5e-3 11e-3"/>
      <geometry>
        <box size="22e-3 15e-3 20e-3"/>
      </geometry>
    </collision>
    <!-- cartriage sledge -->
    <collision>
      <origin rpy="0 0 0" xyz="0 6.8e-3 2.2e-3"/>
      <geometry>
        <box size="22e-3 8.8e-3 3.8e-3"/>
      </geometry>
    </collision>
    <!-- diagonal finger -->
    <collision>
      <origin rpy="0.5235987755982988 0 0" xyz="0 15.9e-3 28.35e-3"/>
      <geometry>
        <box size="17.5e-3 7e-3 23.5e-3"/>
      </geometry>
    </collision>
    <!-- rubber tip with which to grasp -->
    <collision>
      <origin rpy="0 0 0" xyz="0 7.58e-3 45.25e-3"/>
      <geometry>
        <box size="17.5e-3 15.2e-3 18.5e-3"/>
      </geometry>
    </collision>
  </link>
  <link name="fer_rightfinger">
    <visual name="fer_rightfinger_visual">
      <origin rpy="0 0 3.141592653589793" xyz="0 0 0"/>
      <geometry>
        <mesh filename="package://franka_description/meshes/robot_ee/franka_hand_white/visual/finger.dae"/>
      </geometry>
    </visual>
    <!-- screw mount -->
    <collision>
      <origin rpy="0 0 0" xyz="0 -18.5e-3 11e-3"/>
      <geometry>
        <box size="22e-3 15e-3 20e-3"/>
      </geometry>
    </collision>
    <!-- cartriage sledge -->
    <collision>
      <origin rpy="0 0 0" xyz="0 -6.8e-3 2.2e-3"/>
      <geometry>
        <box size="22e-3 8.8e-3 3.8e-3"/>
      </geometry>
    </collision>
    <!-- diagonal finger -->
    <collision>
      <origin rpy="-0.5235987755982988 0 0" xyz="0 -15.9e-3 28.35e-3"/>
      <geometry>
        <box size="17.5e-3 7e-3 23.5e-3"/>
      </geometry>
    </collision>
    <!-- rubber tip with which to grasp -->
    <collision>
      <origin rpy="0 0 0" xyz="0 -7.58e-3 45.25e-3"/>
      <geometry>
        <box size="17.5e-3 15.2e-3 18.5e-3"/>
      </geometry>
    </collision>
  </link>
  <joint name="fer_finger_joint1" type="prismatic">
    <parent link="fer_hand"/>
    <child link="fer_leftfinger"/>
    <origin rpy="0 0 0" xyz="0 0 0.0584"/>
    <axis xyz="0 1 0"/>
    <limit effort="100" lower="0.0" upper="0.04" velocity="0.2"/>
    <dynamics damping="0.3"/>
  </joint>
  <joint name="fer_finger_joint2" type="prismatic">
    <parent link="fer_hand"/>
    <child link="fer_rightfinger"/>
    <origin rpy="0 0 0" xyz="0 0 0.0584"/>
    <axis xyz="0 -1 0"/>
    <limit effort="100" lower="0.0" upper="0.04" velocity="0.2"/>
    <mimic joint="fer_finger_joint1"/>
    <dynamics damping="0.3"/>
  </joint>
  <ros2_control name="FrankaHardwareInterface" type="system">
    <hardware>
      <param name="arm_id">fer</param>
      <param name="prefix"></param>
      <plugin>franka_hardware/FrankaHardwareInterface</plugin>
      <param name="robot_ip"></param>
      <param name="arm_prefix"></param>
    </hardware>
    <joint name="fer_joint1">
      <command_interface name="position"/>
      <command_interface name="velocity"/>
      <command_interface name="effort"/>
      <!-- State Interfaces -->
      <state_interface name="position">
        <param name="initial_value">0.0</param>
      </state_interface>
      <state_interface name="velocity"/>
      <param name="initial_value">0.0</param>
      <state_interface name="effort"/>
    </joint>
    <joint name="fer_joint2">
      <command_interface name="position"/>
      <command_interface name="velocity"/>
      <command_interface name="effort"/>
      <!-- State Interfaces -->
      <state_interface name="position">
        <param name="initial_value">-0.7853981633974483</param>
      </state_interface>
      <state_interface name="velocity"/>
      <param name="initial_value">0.0</param>
      <state_interface name="effort"/>
    </joint>
    <joint name="fer_joint3">
      <command_interface name="position"/>
      <command_interface name="velocity"/>
      <command_interface name="effort"/>
      <!-- State Interfaces -->
      <state_interface name="position">
        <param name="initial_value">0.0</param>
      </state_interface>
      <state_interface name="velocity"/>
      <param name="initial_value">0.0</param>
      <state_interface name="effort"/>
    </joint>
    <joint name="fer_joint4">
      <command_interface name="position"/>
      <command_interface name="velocity"/>
      <command_interface name="effort"/>
      <!-- State Interfaces -->
      <state_interface name="position">
        <param name="initial_value">-2.356194490192345</param>
      </state_interface>
      <state_interface name="velocity"/>
      <param name="initial_value">0.0</param>
      <state_interface name="effort"/>
    </joint>
    <joint name="fer_joint5">
      <command_interface name="position"/>
      <command_interface name="velocity"/>
      <command_interface name="effort"/>
      <!-- State Interfaces -->
      <state_interface name="position">
        <param name="initial_value">0.0</param>
      </state_interface>
      <state_interface name="velocity"/>
      <param name="initial_value">0.0</param>
      <state_interface name="effort"/>
    </joint>
    <joint name="fer_joint6">
      <command_interface name="position"/>
      <command_interface name="velocity"/>
      <command_interface name="effort"/>
      <!-- State Interfaces -->
      <state_interface name="position">
        <param name="initial_value">1.5707963267948966</param>
      </state_interface>
      <state_interface name="velocity"/>
      <param name="initial_value">0.0</param>
      <state_interface name="effort"/>
    </joint>
    <joint name="fer_joint7">
      <command_interface name="position"/>
      <command_interface name="velocity"/>
      <command_interface name="effort"/>
      <!-- State Interfaces -->
      <state_interface name="position">
        <param name="initial_value">0.7853981633974483</param>
      </state_interface>
      <state_interface name="velocity"/>
      <param name="initial_value">0.0</param>
      <state_interface name="effort"/>
    </joint>
  </ros2_control>
  <joint name="ati_mini45_base_joint" type="fixed">
    <parent link="fer_link8"/>
    <child link="ati_mini45"/>
    <origin rpy="0 0 0" xyz="0 0 0"/>
  </joint>
  <!-- sub-link defining detailed meshes for collision with environment -->
  <link name="ati_mini45">
    <visual name="ati_mini45_visual">
      <geometry>
        <mesh filename="package://franka_description/meshes/robot_ee/ft_sensors/visual/ati_mini45.dae"/>
      </geometry>
    </visual>
    <collision name="ati_mini45_collision">
      <geometry>
        <cylinder length="0.0327" radius="0.0315"/>
      </geometry>
      <origin rpy="0 0 0" xyz="0 0 0.01635"/>
    </collision>
    <inertial>
      <origin rpy="0 0 0" xyz="0 0 0.01635"/>
      <mass value="0.163"/>
      <inertia ixx="7.0838e-05" ixy="0" ixz="0" iyy="7.0838e-05" iyz="0" izz="0.000107824"/>
    </inertial>
  </link>
  <joint name="ati_mini45_tool_mount_joint" type="fixed">
    <parent link="ati_mini45"/>
    <child link="ati_mini45_tool_mount"/>
    <origin rpy="0 0 0" xyz="0 0 0.0327"/>
  </joint>
  <link name="ati_mini45_tool_mount"/>
  <joint name="ati_mini45_measurement_reference_joint" type="fixed">
    <parent link="ati_mini45"/>
    <child link="ati_mini45_measurement_reference"/>
    <origin rpy="3.141592653589793 0.0 1.8325957145940461" xyz="0 0 0.01635"/>
  </joint>
  <link name="ati_mini45_measurement_reference"/>
  <ros2_control name="NetFtHardwareInterface" type="sensor">
    <hardware>
      <plugin>net_ft_driver/NetFtHardwareInterface</plugin>
      <param name="sensor_type">ati</param>
      <param name="ip_address"></param>
      <param name="rdt_sampling_rate">2333</param>
      <param name="internal_filter_rate">0</param>
      <param name="use_hardware_biasing">False</param>
    </hardware>
    <sensor name="tcp_fts_sensor">
      <state_interface name="force.x"/>
      <state_interface name="force.y"/>
      <state_interface name="force.z"/>
      <state_interface name="torque.x"/>
      <state_interface name="torque.y"/>
      <state_interface name="torque.z"/>
      <param name="frame_id">tool_link</param>
    </sensor>
    <gpio name="diagnostic">
      <state_interface name="packet_count"/>
      <state_interface name="lost_packets"/>
      <state_interface name="out_of_order_count"/>
      <state_interface name="status"/>
    </gpio>
  </ros2_control>
</robot>
